[2024-03-02T15:06:44.843+0000] {taskinstance.py:1165} INFO - Dependencies all met for <TaskInstance: Batching_Data.Scrapping scheduled__2024-03-02T14:10:00+00:00 [queued]>
[2024-03-02T15:06:44.863+0000] {taskinstance.py:1165} INFO - Dependencies all met for <TaskInstance: Batching_Data.Scrapping scheduled__2024-03-02T14:10:00+00:00 [queued]>
[2024-03-02T15:06:44.864+0000] {taskinstance.py:1362} INFO - 
--------------------------------------------------------------------------------
[2024-03-02T15:06:44.865+0000] {taskinstance.py:1363} INFO - Starting attempt 6 of 6
[2024-03-02T15:06:44.866+0000] {taskinstance.py:1364} INFO - 
--------------------------------------------------------------------------------
[2024-03-02T15:06:44.892+0000] {taskinstance.py:1383} INFO - Executing <Task(PythonOperator): Scrapping> on 2024-03-02 14:10:00+00:00
[2024-03-02T15:06:44.904+0000] {standard_task_runner.py:55} INFO - Started process 228 to run task
[2024-03-02T15:06:44.908+0000] {standard_task_runner.py:82} INFO - Running: ['***', 'tasks', 'run', 'Batching_Data', 'Scrapping', 'scheduled__2024-03-02T14:10:00+00:00', '--job-id', '105', '--raw', '--subdir', 'DAGS_FOLDER/Batching_Data.py', '--cfg-path', '/tmp/tmp7k708tx7']
[2024-03-02T15:06:44.912+0000] {standard_task_runner.py:83} INFO - Job 105: Subtask Scrapping
[2024-03-02T15:06:45.037+0000] {task_command.py:376} INFO - Running <TaskInstance: Batching_Data.Scrapping scheduled__2024-03-02T14:10:00+00:00 [running]> on host 14617ffbd56e
[2024-03-02T15:06:45.223+0000] {taskinstance.py:1592} INFO - Exporting the following env vars:
AIRFLOW_CTX_DAG_OWNER=Bob Sebastian
AIRFLOW_CTX_DAG_ID=Batching_Data
AIRFLOW_CTX_TASK_ID=Scrapping
AIRFLOW_CTX_EXECUTION_DATE=2024-03-02T14:10:00+00:00
AIRFLOW_CTX_TRY_NUMBER=6
AIRFLOW_CTX_DAG_RUN_ID=scheduled__2024-03-02T14:10:00+00:00
[2024-03-02T15:06:54.750+0000] {taskinstance.py:1851} ERROR - Task failed with exception
Traceback (most recent call last):
  File "/home/airflow/.local/lib/python3.7/site-packages/airflow/operators/python.py", line 175, in execute
    return_value = self.execute_callable()
  File "/home/airflow/.local/lib/python3.7/site-packages/airflow/operators/python.py", line 193, in execute_callable
    return self.python_callable(*self.op_args, **self.op_kwargs)
  File "/opt/airflow/dags/Batching_Data.py", line 64, in batching_data
    with open(os.getenv("weight_model"), "r") as json_file:
FileNotFoundError: [Errno 2] No such file or directory: '/opt/model/sub_category_model.json'
[2024-03-02T15:06:54.791+0000] {taskinstance.py:1406} INFO - Marking task as FAILED. dag_id=Batching_Data, task_id=Scrapping, execution_date=20240302T141000, start_date=20240302T150644, end_date=20240302T150654
[2024-03-02T15:06:54.792+0000] {taskinstance.py:1619} ERROR - Error when executing on_failure callback
Traceback (most recent call last):
  File "/home/airflow/.local/lib/python3.7/site-packages/airflow/models/taskinstance.py", line 1457, in _run_raw_task
    self._execute_task_with_callbacks(context, test_mode)
  File "/home/airflow/.local/lib/python3.7/site-packages/airflow/models/taskinstance.py", line 1603, in _execute_task_with_callbacks
    result = self._execute_task(context, task_orig)
  File "/home/airflow/.local/lib/python3.7/site-packages/airflow/models/taskinstance.py", line 1659, in _execute_task
    result = execute_callable(context=context)
  File "/home/airflow/.local/lib/python3.7/site-packages/airflow/operators/python.py", line 175, in execute
    return_value = self.execute_callable()
  File "/home/airflow/.local/lib/python3.7/site-packages/airflow/operators/python.py", line 193, in execute_callable
    return self.python_callable(*self.op_args, **self.op_kwargs)
  File "/opt/airflow/dags/Batching_Data.py", line 64, in batching_data
    with open(os.getenv("weight_model"), "r") as json_file:
FileNotFoundError: [Errno 2] No such file or directory: '/opt/model/sub_category_model.json'

During handling of the above exception, another exception occurred:

Traceback (most recent call last):
  File "/home/airflow/.local/lib/python3.7/site-packages/airflow/models/taskinstance.py", line 1617, in _run_finished_callback
    callback(context)
TypeError: batching_data() takes 0 positional arguments but 1 was given
[2024-03-02T15:06:54.826+0000] {standard_task_runner.py:105} ERROR - Failed to execute job 105 for task Scrapping ([Errno 2] No such file or directory: '/opt/model/sub_category_model.json'; 228)
[2024-03-02T15:06:54.870+0000] {local_task_job.py:164} INFO - Task exited with return code 1
[2024-03-02T15:06:54.912+0000] {local_task_job.py:273} INFO - 0 downstream tasks scheduled from follow-on schedule check
