[2024-03-02T00:20:18.704+0000] {taskinstance.py:1165} INFO - Dependencies all met for <TaskInstance: Batching_Data.Scrapping manual__2024-03-02T00:19:49.138321+00:00 [queued]>
[2024-03-02T00:20:18.716+0000] {taskinstance.py:1165} INFO - Dependencies all met for <TaskInstance: Batching_Data.Scrapping manual__2024-03-02T00:19:49.138321+00:00 [queued]>
[2024-03-02T00:20:18.717+0000] {taskinstance.py:1362} INFO - 
--------------------------------------------------------------------------------
[2024-03-02T00:20:18.718+0000] {taskinstance.py:1363} INFO - Starting attempt 2 of 6
[2024-03-02T00:20:18.718+0000] {taskinstance.py:1364} INFO - 
--------------------------------------------------------------------------------
[2024-03-02T00:20:18.735+0000] {taskinstance.py:1383} INFO - Executing <Task(PythonOperator): Scrapping> on 2024-03-02 00:19:49.138321+00:00
[2024-03-02T00:20:18.746+0000] {standard_task_runner.py:55} INFO - Started process 351 to run task
[2024-03-02T00:20:18.750+0000] {standard_task_runner.py:82} INFO - Running: ['***', 'tasks', 'run', 'Batching_Data', 'Scrapping', 'manual__2024-03-02T00:19:49.138321+00:00', '--job-id', '84', '--raw', '--subdir', 'DAGS_FOLDER/Batching_Data.py', '--cfg-path', '/tmp/tmpdb3pzh68']
[2024-03-02T00:20:18.752+0000] {standard_task_runner.py:83} INFO - Job 84: Subtask Scrapping
[2024-03-02T00:20:18.829+0000] {task_command.py:376} INFO - Running <TaskInstance: Batching_Data.Scrapping manual__2024-03-02T00:19:49.138321+00:00 [running]> on host 14617ffbd56e
[2024-03-02T00:20:18.929+0000] {taskinstance.py:1592} INFO - Exporting the following env vars:
AIRFLOW_CTX_DAG_OWNER=Bob Sebastian
AIRFLOW_CTX_DAG_ID=Batching_Data
AIRFLOW_CTX_TASK_ID=Scrapping
AIRFLOW_CTX_EXECUTION_DATE=2024-03-02T00:19:49.138321+00:00
AIRFLOW_CTX_TRY_NUMBER=2
AIRFLOW_CTX_DAG_RUN_ID=manual__2024-03-02T00:19:49.138321+00:00
[2024-03-02T00:20:18.952+0000] {taskinstance.py:1851} ERROR - Task failed with exception
Traceback (most recent call last):
  File "/home/airflow/.local/lib/python3.7/site-packages/selenium/webdriver/common/service.py", line 76, in start
    stdin=PIPE)
  File "/usr/local/lib/python3.7/subprocess.py", line 800, in __init__
    restore_signals, start_new_session)
  File "/usr/local/lib/python3.7/subprocess.py", line 1551, in _execute_child
    raise child_exception_type(errno_num, err_msg, err_filename)
FileNotFoundError: [Errno 2] No such file or directory: '@pollyjs/standalone-chrome': '@pollyjs/standalone-chrome'

During handling of the above exception, another exception occurred:

Traceback (most recent call last):
  File "/home/airflow/.local/lib/python3.7/site-packages/airflow/operators/python.py", line 175, in execute
    return_value = self.execute_callable()
  File "/home/airflow/.local/lib/python3.7/site-packages/airflow/operators/python.py", line 193, in execute_callable
    return self.python_callable(*self.op_args, **self.op_kwargs)
  File "/opt/airflow/dags/Batching_Data.py", line 42, in batching_data
    service.start()
  File "/home/airflow/.local/lib/python3.7/site-packages/selenium/webdriver/common/service.py", line 83, in start
    os.path.basename(self.path), self.start_error_message)
selenium.common.exceptions.WebDriverException: Message: 'standalone-chrome' executable needs to be in PATH. Please see https://sites.google.com/a/chromium.org/chromedriver/home

[2024-03-02T00:20:18.972+0000] {taskinstance.py:1406} INFO - Marking task as UP_FOR_RETRY. dag_id=Batching_Data, task_id=Scrapping, execution_date=20240302T001949, start_date=20240302T002018, end_date=20240302T002018
[2024-03-02T00:20:18.990+0000] {standard_task_runner.py:105} ERROR - Failed to execute job 84 for task Scrapping (Message: 'standalone-chrome' executable needs to be in PATH. Please see https://sites.google.com/a/chromium.org/chromedriver/home
; 351)
[2024-03-02T00:20:19.041+0000] {local_task_job.py:164} INFO - Task exited with return code 1
[2024-03-02T00:20:19.074+0000] {local_task_job.py:273} INFO - 0 downstream tasks scheduled from follow-on schedule check
